Workbook

Sheet KP_Client
A1: OFERTĂ COMERCIALĂ
A2: Sistem automat de stingere incendiu
A4: Client: | B4: ________________________ | E4: TVA: | F4: =Setari!$B$2 -> 0.2
A5: Obiect: | B5: ________________________ | E5: Valută: | F5: =Setari!$B$4 -> MDL
A6: Data: | B6: =TODAY() -> 46189
A7: Valabilitate ofertă: | B7: 15 zile
A9: 1. Sistem sprinkler
A10: Nr | B10: Denumire | C10: U.M. | D10: Cantitate | E10: Preț unitar | F10: Sumă
A45: =IF(Introducere_interna!$B15="","",10) | B45: =IF(Introducere_interna!$B15="","",Introducere_interna!$C15) | C45: =IF(Introducere_interna!$B15="","",Introducere_interna!$D15) | D45: =IF(Introducere_interna!$B15="","",Introducere_interna!$E15) | E45: =IF(Introducere_interna!$B15="","",Introducere_interna!$F15) | F45: =IF(Introducere_interna!$B15="","",Introducere_interna!$G15)
A46: =IF(Introducere_interna!$B16="","",11) | B46: =IF(Introducere_interna!$B16="","",Introducere_interna!$C16) | C46: =IF(Introducere_interna!$B16="","",Introducere_interna!$D16) | D46: =IF(Introducere_interna!$B16="","",Introducere_interna!$E16) | E46: =IF(Introducere_interna!$B16="","",Introducere_interna!$F16) | F46: =IF(Introducere_interna!$B16="","",Introducere_interna!$G16)
A47: =IF(Introducere_interna!$B17="","",12) | B47: =IF(Introducere_interna!$B17="","",Introducere_interna!$C17) | C47: =IF(Introducere_interna!$B17="","",Introducere_interna!$D17) | D47: =IF(Introducere_interna!$B17="","",Introducere_interna!$E17) | E47: =IF(Introducere_interna!$B17="","",Introducere_interna!$F17) | F47: =IF(Introducere_interna!$B17="","",Introducere_interna!$G17)
A48: =IF(Introducere_interna!$B18="","",13) | B48: =IF(Introducere_interna!$B18="","",Introducere_interna!$C18) | C48: =IF(Introducere_interna!$B18="","",Introducere_interna!$D18) | D48: =IF(Introducere_interna!$B18="","",Introducere_interna!$E18) | E48: =IF(Introducere_interna!$B18="","",Introducere_interna!$F18) | F48: =IF(Introducere_interna!$B18="","",Introducere_interna!$G18)
A49: =IF(Introducere_interna!$B19="","",14) | B49: =IF(Introducere_interna!$B19="","",Introducere_interna!$C19) | C49: =IF(Introducere_interna!$B19="","",Introducere_interna!$D19) | D49: =IF(Introducere_interna!$B19="","",Introducere_interna!$E19) | E49: =IF(Introducere_interna!$B19="","",Introducere_interna!$F19) | F49: =IF(Introducere_interna!$B19="","",Introducere_interna!$G19)
A50: =IF(Introducere_interna!$B20="","",15) | B50: =IF(Introducere_interna!$B20="","",Introducere_interna!$C20) | C50: =IF(Introducere_interna!$B20="","",Introducere_interna!$D20) | D50: =IF(Introducere_interna!$B20="","",Introducere_interna!$E20) | E50: =IF(Introducere_interna!$B20="","",Introducere_interna!$F20) | F50: =IF(Introducere_interna!$B20="","",Introducere_interna!$G20)
A51: Subtotal 1. sistem sprinkler | F51: =SUM(F20:F50) -> 0
A53: 2. Nod de control și comandă
A54: Nr | B54: Denumire | C54: U.M. | D54: Cantitate | E54: Preț unitar | F54: Sumă
A74: =IF(Introducere_interna!$B22="","",2) | B74: =IF(Introducere_interna!$B22="","",Introducere_interna!$C22) | C74: =IF(Introducere_interna!$B22="","",Introducere_interna!$D22) | D74: =IF(Introducere_interna!$B22="","",Introducere_interna!$E22) | E74: =IF(Introducere_interna!$B22="","",Introducere_interna!$F22) | F74: =IF(Introducere_interna!$B22="","",Introducere_interna!$G22)
A75: =IF(Introducere_interna!$B23="","",3) | B75: =IF(Introducere_interna!$B23="","",Introducere_interna!$C23) | C75: =IF(Introducere_interna!$B23="","",Introducere_interna!$D23) | D75: =IF(Introducere_interna!$B23="","",Introducere_interna!$E23) | E75: =IF(Introducere_interna!$B23="","",Introducere_interna!$F23) | F75: =IF(Introducere_interna!$B23="","",Introducere_interna!$G23)
A76: =IF(Introducere_interna!$B24="","",4) | B76: =IF(Introducere_interna!$B24="","",Introducere_interna!$C24) | C76: =IF(Introducere_interna!$B24="","",Introducere_interna!$D24) | D76: =IF(Introducere_interna!$B24="","",Introducere_interna!$E24) | E76: =IF(Introducere_interna!$B24="","",Introducere_interna!$F24) | F76: =IF(Introducere_interna!$B24="","",Introducere_interna!$G24)
A77: =IF(Introducere_interna!$B25="","",5) | B77: =IF(Introducere_interna!$B25="","",Introducere_interna!$C25) | C77: =IF(Introducere_interna!$B25="","",Introducere_interna!$D25) | D77: =IF(Introducere_interna!$B25="","",Introducere_interna!$E25) | E77: =IF(Introducere_interna!$B25="","",Introducere_interna!$F25) | F77: =IF(Introducere_interna!$B25="","",Introducere_interna!$G25)
A78: =IF(Introducere_interna!$B26="","",6) | B78: =IF(Introducere_interna!$B26="","",Introducere_interna!$C26) | C78: =IF(Introducere_interna!$B26="","",Introducere_interna!$D26) | D78: =IF(Introducere_interna!$B26="","",Introducere_interna!$E26) | E78: =IF(Introducere_interna!$B26="","",Introducere_interna!$F26) | F78: =IF(Introducere_interna!$B26="","",Introducere_interna!$G26)
A79: =IF(Introducere_interna!$B27="","",7) | B79: =IF(Introducere_interna!$B27="","",Introducere_interna!$C27) | C79: =IF(Introducere_interna!$B27="","",Introducere_interna!$D27) | D79: =IF(Introducere_interna!$B27="","",Introducere_interna!$E27) | E79: =IF(Introducere_interna!$B27="","",Introducere_interna!$F27) | F79: =IF(Introducere_interna!$B27="","",Introducere_interna!$G27)
A80: =IF(Introducere_interna!$B28="","",8) | B80: =IF(Introducere_interna!$B28="","",Introducere_interna!$C28) | C80: =IF(Introducere_interna!$B28="","",Introducere_interna!$D28) | D80: =IF(Introducere_interna!$B28="","",Introducere_interna!$E28) | E80: =IF(Introducere_interna!$B28="","",Introducere_interna!$F28) | F80: =IF(Introducere_interna!$B28="","",Introducere_interna!$G28)
A81: =IF(Introducere_interna!$B29="","",9) | B81: =IF(Introducere_interna!$B29="","",Introducere_interna!$C29) | C81: =IF(Introducere_interna!$B29="","",Introducere_interna!$D29) | D81: =IF(Introducere_interna!$B29="","",Introducere_interna!$E29) | E81: =IF(Introducere_interna!$B29="","",Introducere_interna!$F29) | F81: =IF(Introducere_interna!$B29="","",Introducere_interna!$G29)
A82: =IF(Introducere_interna!$B30="","",10) | B82: =IF(Introducere_interna!$B30="","",Introducere_interna!$C30) | C82: =IF(Introducere_interna!$B30="","",Introducere_interna!$D30) | D82: =IF(Introducere_interna!$B30="","",Introducere_interna!$E30) | E82: =IF(Introducere_interna!$B30="","",Introducere_interna!$F30) | F82: =IF(Introducere_interna!$B30="","",Introducere_interna!$G30)
A83: =IF(Introducere_interna!$B31="","",11) | B83: =IF(Introducere_interna!$B31="","",Introducere_interna!$C31) | C83: =IF(Introducere_interna!$B31="","",Introducere_interna!$D31) | D83: =IF(Introducere_interna!$B31="","",Introducere_interna!$E31) | E83: =IF(Introducere_interna!$B31="","",Introducere_interna!$F31) | F83: =IF(Introducere_interna!$B31="","",Introducere_interna!$G31)
A84: =IF(Introducere_interna!$B32="","",12) | B84: =IF(Introducere_interna!$B32="","",Introducere_interna!$C32) | C84: =IF(Introducere_interna!$B32="","",Introducere_interna!$D32) | D84: =IF(Introducere_interna!$B32="","",Introducere_interna!$E32) | E84: =IF(Introducere_interna!$B32="","",Introducere_interna!$F32) | F84: =IF(Introducere_interna!$B32="","",Introducere_interna!$G32)
A85: =IF(Introducere_interna!$B33="","",13) | B85: =IF(Introducere_interna!$B33="","",Introducere_interna!$C33) | C85: =IF(Introducere_interna!$B33="","",Introducere_interna!$D33) | D85: =IF(Introducere_interna!$B33="","",Introducere_interna!$E33) | E85: =IF(Introducere_interna!$B33="","",Introducere_interna!$F33) | F85: =IF(Introducere_interna!$B33="","",Introducere_interna!$G33)
A86: =IF(Introducere_interna!$B34="","",14) | B86: =IF(Introducere_interna!$B34="","",Introducere_interna!$C34) | C86: =IF(Introducere_interna!$B34="","",Introducere_interna!$D34) | D86: =IF(Introducere_interna!$B34="","",Introducere_interna!$E34) | E86: =IF(Introducere_interna!$B34="","",Introducere_interna!$F34) | F86: =IF(Introducere_interna!$B34="","",Introducere_interna!$G34)
A87: =IF(Introducere_interna!$B35="","",15) | B87: =IF(Introducere_interna!$B35="","",Introducere_interna!$C35) | C87: =IF(Introducere_interna!$B35="","",Introducere_interna!$D35) | D87: =IF(Introducere_interna!$B35="","",Introducere_interna!$E35) | E87: =IF(Introducere_interna!$B35="","",Introducere_interna!$F35) | F87: =IF(Introducere_interna!$B35="","",Introducere_interna!$G35)
A88: Subtotal 2. nod de control și comandă | F88: =SUM(F73:F87) -> 0
A90: 3. Stație de pompare
A91: Nr | B91: Denumire | C91: U.M. | D91: Cantitate | E91: Preț unitar | F91: Sumă
A92: =IF(Introducere_interna!$B36="","",1) | B92: =IF(Introducere_interna!$B36="","",Introducere_interna!$C36) | C92: =IF(Introducere_interna!$B36="","",Introducere_interna!$D36) | D92: =IF(Introducere_interna!$B36="","",Introducere_interna!$E36) | E92: =IF(Introducere_interna!$B36="","",Introducere_interna!$F36) | F92: =IF(Introducere_interna!$B36="","",Introducere_interna!$G36)
A93: =IF(Introducere_interna!$B37="","",2) | B93: =IF(Introducere_interna!$B37="","",Introducere_interna!$C37) | C93: =IF(Introducere_interna!$B37="","",Introducere_interna!$D37) | D93: =IF(Introducere_interna!$B37="","",Introducere_interna!$E37) | E93: =IF(Introducere_interna!$B37="","",Introducere_interna!$F37) | F93: =IF(Introducere_interna!$B37="","",Introducere_interna!$G37)
A110: =IF(Introducere_interna!$B43="","",8) | B110: =IF(Introducere_interna!$B43="","",Introducere_interna!$C43) | C110: =IF(Introducere_interna!$B43="","",Introducere_interna!$D43) | D110: =IF(Introducere_interna!$B43="","",Introducere_interna!$E43) | E110: =IF(Introducere_interna!$B43="","",Introducere_interna!$F43) | F110: =IF(Introducere_interna!$B43="","",Introducere_interna!$G43)
A111: =IF(Introducere_interna!$B44="","",9) | B111: =IF(Introducere_interna!$B44="","",Introducere_interna!$C44) | C111: =IF(Introducere_interna!$B44="","",Introducere_interna!$D44) | D111: =IF(Introducere_interna!$B44="","",Introducere_interna!$E44) | E111: =IF(Introducere_interna!$B44="","",Introducere_interna!$F44) | F111: =IF(Introducere_interna!$B44="","",Introducere_interna!$G44)
A112: =IF(Introducere_interna!$B45="","",10) | B112: =IF(Introducere_interna!$B45="","",Introducere_interna!$C45) | C112: =IF(Introducere_interna!$B45="","",Introducere_interna!$D45) | D112: =IF(Introducere_interna!$B45="","",Introducere_interna!$E45) | E112: =IF(Introducere_interna!$B45="","",Introducere_interna!$F45) | F112: =IF(Introducere_interna!$B45="","",Introducere_interna!$G45)
A113: =IF(Introducere_interna!$B46="","",11) | B113: =IF(Introducere_interna!$B46="","",Introducere_interna!$C46) | C113: =IF(Introducere_interna!$B46="","",Introducere_interna!$D46) | D113: =IF(Introducere_interna!$B46="","",Introducere_interna!$E46) | E113: =IF(Introducere_interna!$B46="","",Introducere_interna!$F46) | F113: =IF(Introducere_interna!$B46="","",Introducere_interna!$G46)
...

Sheet Introducere_interna
A1: Introducere internă – aici se completează codurile și cantitățile
A3: Instrucțiune: | B3: Completezi doar Cod produs și Cantitate. Clientul nu vede acest sheet dacă exporți KP_Client în PDF.
A5: Secțiune | B5: Cod produs | C5: Denumire | D5: UM | E5: Cantitate | F5: Preț unitar | G5: Sumă | H5: Status
A6: 1. Sistem sprinkler | B6: SPR-CBSO-57 | C6: =IFERROR(VLOOKUP($B6,Baza_preturi!$A:$K,3,FALSE),"") -> Sprinkler incendiu CBSO-PVo 0.08 R1/2 P57.B3 | D6: =IFERROR(VLOOKUP($B6,Baza_preturi!$A:$K,6,FALSE),"") -> buc | E6: 850 | F6: =IFERROR(VLOOKUP($B6,Baza_preturi!$A:$K,9,FALSE),"") -> 156.1125 | G6: =IF(OR($E6="", $F6=""),"", $E6*$F6) -> 132695.62 | H6: =IF($B6="","",IFERROR(IF(VLOOKUP($B6,Baza_preturi!$A:$A,1,FALSE)=$B6,"OK","VERIFICĂ"),"COD NU EXISTĂ")) -> OK
A7: 1. Sistem sprinkler | B7: TEV-ZN-DN80 | C7: =IFERROR(VLOOKUP($B7,Baza_preturi!$A:$K,3,FALSE),"") | D7: =IFERROR(VLOOKUP($B7,Baza_preturi!$A:$K,6,FALSE),"") | E7: 120 | F7: =IFERROR(VLOOKUP($B7,Baza_preturi!$A:$K,9,FALSE),"") | G7: =IF(OR($E7="", $F7=""),"", $E7*$F7) | H7: =IF($B7="","",IFERROR(IF(VLOOKUP($B7,Baza_preturi!$A:$A,1,FALSE)=$B7,"OK","VERIFICĂ"),"COD NU EXISTĂ")) -> COD NU EXISTĂ
A8: 1. Sistem sprinkler | B8: TEV-ZN-DN15-2.2 | C8: =IFERROR(VLOOKUP($B8,Baza_preturi!$A:$K,3,FALSE),"") -> Țeavă zincată DN15*2.2mm | D8: =IFERROR(VLOOKUP($B8,Baza_preturi!$A:$K,6,FALSE),"") -> m | E8: 500 | F8: =IFERROR(VLOOKUP($B8,Baza_preturi!$A:$K,9,FALSE),"") | G8: =IF(OR($E8="", $F8=""),"", $E8*$F8) | H8: =IF($B8="","",IFERROR(IF(VLOOKUP($B8,Baza_preturi!$A:$A,1,FALSE)=$B8,"OK","VERIFICĂ"),"COD NU EXISTĂ")) -> OK
A9: 1. Sistem sprinkler | B9: TEV-ZN-DN15-2.8 | C9: =IFERROR(VLOOKUP($B9,Baza_preturi!$A:$K,3,FALSE),"") -> Țeavă zincată DN15*2.8mm | D9: =IFERROR(VLOOKUP($B9,Baza_preturi!$A:$K,6,FALSE),"") -> m | E9: 20 | F9: =IFERROR(VLOOKUP($B9,Baza_preturi!$A:$K,9,FALSE),"") | G9: =IF(OR($E9="", $F9=""),"", $E9*$F9) | H9: =IF($B9="","",IFERROR(IF(VLOOKUP($B9,Baza_preturi!$A:$A,1,FALSE)=$B9,"OK","VERIFICĂ"),"COD NU EXISTĂ")) -> OK
A10: 1. Sistem sprinkler | B10: TEV-ZN-DN32-2.8 | C10: =IFERROR(VLOOKUP($B10,Baza_preturi!$A:$K,3,FALSE),"") -> Țeavă zincată DN32*2.8mm | D10: =IFERROR(VLOOKUP($B10,Baza_preturi!$A:$K,6,FALSE),"") -> m | E10: 50 | F10: =IFERROR(VLOOKUP($B10,Baza_preturi!$A:$K,9,FALSE),"") -> 52.5 | G10: =IF(OR($E10="", $F10=""),"", $E10*$F10) -> 2625 | H10: =IF($B10="","",IFERROR(IF(VLOOKUP($B10,Baza_preturi!$A:$A,1,FALSE)=$B10,"OK","VERIFICĂ"),"COD NU EXISTĂ")) -> OK
A11: 1. Sistem sprinkler | B11: TEV-ZN-DN50 | C11: =IFERROR(VLOOKUP($B11,Baza_preturi!$A:$K,3,FALSE),"") | D11: =IFERROR(VLOOKUP($B11,Baza_preturi!$A:$K,6,FALSE),"") | F11: =IFERROR(VLOOKUP($B11,Baza_preturi!$A:$K,9,FALSE),"") | G11: =IF(OR($E11="", $F11=""),"", $E11*$F11) | H11: =IF($B11="","",IFERROR(IF(VLOOKUP($B11,Baza_preturi!$A:$A,1,FALSE)=$B11,"OK","VERIFICĂ"),"COD NU EXISTĂ")) -> COD NU EXISTĂ
A12: 1. Sistem sprinkler | B12: TEV-ZN-DN15-2.2 | C12: =IFERROR(VLOOKUP($B12,Baza_preturi!$A:$K,3,FALSE),"") -> Țeavă zincată DN15*2.2mm | D12: =IFERROR(VLOOKUP($B12,Baza_preturi!$A:$K,6,FALSE),"") -> m | E12: 225 | F12: =IFERROR(VLOOKUP($B12,Baza_preturi!$A:$K,9,FALSE),"") | G12: =IF(OR($E12="", $F12=""),"", $E12*$F12) | H12: =IF($B12="","",IFERROR(IF(VLOOKUP($B12,Baza_preturi!$A:$A,1,FALSE)=$B12,"OK","VERIFICĂ"),"COD NU EXISTĂ")) -> OK
A13: 1. Sistem sprinkler | C13: =IFERROR(VLOOKUP($B13,Baza_preturi!$A:$K,3,FALSE),"") | D13: =IFERROR(VLOOKUP($B13,Baza_preturi!$A:$K,6,FALSE),"") | F13: =IFERROR(VLOOKUP($B13,Baza_preturi!$A:$K,9,FALSE),"") | G13: =IF(OR($E13="", $F13=""),"", $E13*$F13) | H13: =IF($B13="","",IFERROR(IF(VLOOKUP($B13,Baza_preturi!$A:$A,1,FALSE)=$B13,"OK","VERIFICĂ"),"COD NU EXISTĂ"))
A14: 1. Sistem sprinkler | C14: =IFERROR(VLOOKUP($B14,Baza_preturi!$A:$K,3,FALSE),"") | D14: =IFERROR(VLOOKUP($B14,Baza_preturi!$A:$K,6,FALSE),"") | F14: =IFERROR(VLOOKUP($B14,Baza_preturi!$A:$K,9,FALSE),"") | G14: =IF(OR($E14="", $F14=""),"", $E14*$F14) | H14: =IF($B14="","",IFERROR(IF(VLOOKUP($B14,Baza_preturi!$A:$A,1,FALSE)=$B14,"OK","VERIFICĂ"),"COD NU EXISTĂ"))
A15: 1. Sistem sprinkler | C15: =IFERROR(VLOOKUP($B15,Baza_preturi!$A:$K,3,FALSE),"") | D15: =IFERROR(VLOOKUP($B15,Baza_preturi!$A:$K,6,FALSE),"") | F15: =IFERROR(VLOOKUP($B15,Baza_preturi!$A:$K,9,FALSE),"") | G15: =IF(OR($E15="", $F15=""),"", $E15*$F15) | H15: =IF($B15="","",IFERROR(IF(VLOOKUP($B15,Baza_preturi!$A:$A,1,FALSE)=$B15,"OK","VERIFICĂ"),"COD NU EXISTĂ"))
A16: 1. Sistem sprinkler | C16: =IFERROR(VLOOKUP($B16,Baza_preturi!$A:$K,3,FALSE),"") | D16: =IFERROR(VLOOKUP($B16,Baza_preturi!$A:$K,6,FALSE),"") | F16: =IFERROR(VLOOKUP($B16,Baza_preturi!$A:$K,9,FALSE),"") | G16: =IF(OR($E16="", $F16=""),"", $E16*$F16) | H16: =IF($B16="","",IFERROR(IF(VLOOKUP($B16,Baza_preturi!$A:$A,1,FALSE)=$B16,"OK","VERIFICĂ"),"COD NU EXISTĂ"))
A17: 1. Sistem sprinkler | C17: =IFERROR(VLOOKUP($B17,Baza_preturi!$A:$K,3,FALSE),"") | D17: =IFERROR(VLOOKUP($B17,Baza_preturi!$A:$K,6,FALSE),"") | F17: =IFERROR(VLOOKUP($B17,Baza_preturi!$A:$K,9,FALSE),"") | G17: =IF(OR($E17="", $F17=""),"", $E17*$F17) | H17: =IF($B17="","",IFERROR(IF(VLOOKUP($B17,Baza_preturi!$A:$A,1,FALSE)=$B17,"OK","VERIFICĂ"),"COD NU EXISTĂ"))
A18: 1. Sistem sprinkler | C18: =IFERROR(VLOOKUP($B18,Baza_preturi!$A:$K,3,FALSE),"") | D18: =IFERROR(VLOOKUP($B18,Baza_preturi!$A:$K,6,FALSE),"") | F18: =IFERROR(VLOOKUP($B18,Baza_preturi!$A:$K,9,FALSE),"") | G18: =IF(OR($E18="", $F18=""),"", $E18*$F18) | H18: =IF($B18="","",IFERROR(IF(VLOOKUP($B18,Baza_preturi!$A:$A,1,FALSE)=$B18,"OK","VERIFICĂ"),"COD NU EXISTĂ"))
A19: 1. Sistem sprinkler | C19: =IFERROR(VLOOKUP($B19,Baza_preturi!$A:$K,3,FALSE),"") | D19: =IFERROR(VLOOKUP($B19,Baza_preturi!$A:$K,6,FALSE),"") | F19: =IFERROR(VLOOKUP($B19,Baza_preturi!$A:$K,9,FALSE),"") | G19: =IF(OR($E19="", $F19=""),"", $E19*$F19) | H19: =IF($B19="","",IFERROR(IF(VLOOKUP($B19,Baza_preturi!$A:$A,1,FALSE)=$B19,"OK","VERIFICĂ"),"COD NU EXISTĂ"))
A20: 1. Sistem sprinkler | C20: =IFERROR(VLOOKUP($B20,Baza_preturi!$A:$K,3,FALSE),"") | D20: =IFERROR(VLOOKUP($B20,Baza_preturi!$A:$K,6,FALSE),"") | F20: =IFERROR(VLOOKUP($B20,Baza_preturi!$A:$K,9,FALSE),"") | G20: =IF(OR($E20="", $F20=""),"", $E20*$F20) | H20: =IF($B20="","",IFERROR(IF(VLOOKUP($B20,Baza_preturi!$A:$A,1,FALSE)=$B20,"OK","VERIFICĂ"),"COD NU EXISTĂ"))
A21: 2. Nod de control și comandă | B21: VAN-FL-DN50 | C21: =IFERROR(VLOOKUP($B21,Baza_preturi!$A:$K,3,FALSE),"") -> Vană fluture DN50 PN16 | D21: =IFERROR(VLOOKUP($B21,Baza_preturi!$A:$K,6,FALSE),"") -> buc | F21: =IFERROR(VLOOKUP($B21,Baza_preturi!$A:$K,9,FALSE),"") -> 700 | G21: =IF(OR($E21="", $F21=""),"", $E21*$F21) | H21: =IF($B21="","",IFERROR(IF(VLOOKUP($B21,Baza_preturi!$A:$A,1,FALSE)=$B21,"OK","VERIFICĂ"),"COD NU EXISTĂ")) -> OK
A22: 2. Nod de control și comandă | C22: =IFERROR(VLOOKUP($B22,Baza_preturi!$A:$K,3,FALSE),"") | D22: =IFERROR(VLOOKUP($B22,Baza_preturi!$A:$K,6,FALSE),"") | F22: =IFERROR(VLOOKUP($B22,Baza_preturi!$A:$K,9,FALSE),"") | G22: =IF(OR($E22="", $F22=""),"", $E22*$F22) | H22: =IF($B22="","",IFERROR(IF(VLOOKUP($B22,Baza_preturi!$A:$A,1,FALSE)=$B22,"OK","VERIFICĂ"),"COD NU EXISTĂ"))
A23: 2. Nod de control și comandă | C23: =IFERROR(VLOOKUP($B23,Baza_preturi!$A:$K,3,FALSE),"") | D23: =IFERROR(VLOOKUP($B23,Baza_preturi!$A:$K,6,FALSE),"") | F23: =IFERROR(VLOOKUP($B23,Baza_preturi!$A:$K,9,FALSE),"") | G23: =IF(OR($E23="", $F23=""),"", $E23*$F23) | H23: =IF($B23="","",IFERROR(IF(VLOOKUP($B23,Baza_preturi!$A:$A,1,FALSE)=$B23,"OK","VERIFICĂ"),"COD NU EXISTĂ"))
A24: 2. Nod de control și comandă | C24: =IFERROR(VLOOKUP($B24,Baza_preturi!$A:$K,3,FALSE),"") | D24: =IFERROR(VLOOKUP($B24,Baza_preturi!$A:$K,6,FALSE),"") | F24: =IFERROR(VLOOKUP($B24,Baza_preturi!$A:$K,9,FALSE),"") | G24: =IF(OR($E24="", $F24=""),"", $E24*$F24) | H24: =IF($B24="","",IFERROR(IF(VLOOKUP($B24,Baza_preturi!$A:$A,1,FALSE)=$B24,"OK","VERIFICĂ"),"COD NU EXISTĂ"))
A25: 2. Nod de control și comandă | C25: =IFERROR(VLOOKUP($B25,Baza_preturi!$A:$K,3,FALSE),"") | D25: =IFERROR(VLOOKUP($B25,Baza_preturi!$A:$K,6,FALSE),"") | F25: =IFERROR(VLOOKUP($B25,Baza_preturi!$A:$K,9,FALSE),"") | G25: =IF(OR($E25="", $F25=""),"", $E25*$F25) | H25: =IF($B25="","",IFERROR(IF(VLOOKUP($B25,Baza_preturi!$A:$A,1,FALSE)=$B25,"OK","VERIFICĂ"),"COD NU EXISTĂ"))
A26: 2. Nod de control și comandă | C26: =IFERROR(VLOOKUP($B26,Baza_preturi!$A:$K,3,FALSE),"") | D26: =IFERROR(VLOOKUP($B26,Baza_preturi!$A:$K,6,FALSE),"") | F26: =IFERROR(VLOOKUP($B26,Baza_preturi!$A:$K,9,FALSE),"") | G26: =IF(OR($E26="", $F26=""),"", $E26*$F26) | H26: =IF($B26="","",IFERROR(IF(VLOOKUP($B26,Baza_preturi!$A:$A,1,FALSE)=$B26,"OK","VERIFICĂ"),"COD NU EXISTĂ"))
A27: 2. Nod de control și comandă | C27: =IFERROR(VLOOKUP($B27,Baza_preturi!$A:$K,3,FALSE),"") | D27: =IFERROR(VLOOKUP($B27,Baza_preturi!$A:$K,6,FALSE),"") | F27: =IFERROR(VLOOKUP($B27,Baza_preturi!$A:$K,9,FALSE),"") | G27: =IF(OR($E27="", $F27=""),"", $E27*$F27) | H27: =IF($B27="","",IFERROR(IF(VLOOKUP($B27,Baza_preturi!$A:$A,1,FALSE)=$B27,"OK","VERIFICĂ"),"COD NU EXISTĂ"))
A28: 2. Nod de control și comandă | C28: =IFERROR(VLOOKUP($B28,Baza_preturi!$A:$K,3,FALSE),"") | D28: =IFERROR(VLOOKUP($B28,Baza_preturi!$A:$K,6,FALSE),"") | F28: =IFERROR(VLOOKUP($B28,Baza_preturi!$A:$K,9,FALSE),"") | G28: =IF(OR($E28="", $F28=""),"", $E28*$F28) | H28: =IF($B28="","",IFERROR(IF(VLOOKUP($B28,Baza_preturi!$A:$A,1,FALSE)=$B28,"OK","VERIFICĂ"),"COD NU EXISTĂ"))
A29: 2. Nod de control și comandă | C29: =IFERROR(VLOOKUP($B29,Baza_preturi!$A:$K,3,FALSE),"") | D29: =IFERROR(VLOOKUP($B29,Baza_preturi!$A:$K,6,FALSE),"") | F29: =IFERROR(VLOOKUP($B29,Baza_preturi!$A:$K,9,FALSE),"") | G29: =IF(OR($E29="", $F29=""),"", $E29*$F29) | H29: =IF($B29="","",IFERROR(IF(VLOOKUP($B29,Baza_preturi!$A:$A,1,FALSE)=$B29,"OK","VERIFICĂ"),"COD NU EXISTĂ"))
A30: 2. Nod de control și comandă | C30: =IFERROR(VLOOKUP($B30,Baza_preturi!$A:$K,3,FALSE),"") | D30: =IFERROR(VLOOKUP($B30,Baza_preturi!$A:$K,6,FALSE),"") | F30: =IFERROR(VLOOKUP($B30,Baza_preturi!$A:$K,9,FALSE),"") | G30: =IF(OR($E30="", $F30=""),"", $E30*$F30) | H30: =IF($B30="","",IFERROR(IF(VLOOKUP($B30,Baza_preturi!$A:$A,1,FALSE)=$B30,"OK","VERIFICĂ"),"COD NU EXISTĂ"))
A31: 2. Nod de control și comandă | C31: =IFERROR(VLOOKUP($B31,Baza_preturi!$A:$K,3,FALSE),"") | D31: =IFERROR(VLOOKUP($B31,Baza_preturi!$A:$K,6,FALSE),"") | F31: =IFERROR(VLOOKUP($B31,Baza_preturi!$A:$K,9,FALSE),"") | G31: =IF(OR($E31="", $F31=""),"", $E31*$F31) | H31: =IF($B31="","",IFERROR(IF(VLOOKUP($B31,Baza_preturi!$A:$A,1,FALSE)=$B31,"OK","VERIFICĂ"),"COD NU EXISTĂ"))
A32: 2. Nod de control și comandă | C32: =IFERROR(VLOOKUP($B32,Baza_preturi!$A:$K,3,FALSE),"") | D32: =IFERROR(VLOOKUP($B32,Baza_preturi!$A:$K,6,FALSE),"") | F32: =IFERROR(VLOOKUP($B32,Baza_preturi!$A:$K,9,FALSE),"") | G32: =IF(OR($E32="", $F32=""),"", $E32*$F32) | H32: =IF($B32="","",IFERROR(IF(VLOOKUP($B32,Baza_preturi!$A:$A,1,FALSE)=$B32,"OK","VERIFICĂ"),"COD NU EXISTĂ"))
A33: 2. Nod de control și comandă | C33: =IFERROR(VLOOKUP($B33,Baza_preturi!$A:$K,3,FALSE),"") | D33: =IFERROR(VLOOKUP($B33,Baza_preturi!$A:$K,6,FALSE),"") | F33: =IFERROR(VLOOKUP($B33,Baza_preturi!$A:$K,9,FALSE),"") | G33: =IF(OR($E33="", $F33=""),"", $E33*$F33) | H33: =IF($B33="","",IFERROR(IF(VLOOKUP($B33,Baza_preturi!$A:$A,1,FALSE)=$B33,"OK","VERIFICĂ"),"COD NU EXISTĂ"))
... A38: 3. Stație de pompare | C38: =IFERROR(VLOOKUP($B38,Baza_preturi!$A:$K,3,FALSE),"") | D38: =IFERROR(VLOOKUP($B38,Baza_preturi!$A:$K,6,FALSE),"") | F38: =IFERROR(VLOOKUP($B38,Baza_preturi!$A:$K,9,FALSE),"") | G38: =IF(OR($E38="", $F38=""),"", $E38*$F38) | H38: =IF($B38="","",IFERROR(IF(VLOOKUP($B38,Baza_preturi!$A:$A,1,FALSE)=$B38,"OK","VERIFICĂ"),"COD NU EXISTĂ"))
A39: 3. Stație de pompare | B39: REZ-APA | C39: =IFERROR(VLOOKUP($B39,Baza_preturi!$A:$K,3,FALSE),"") -> Rezervor apă | D39: =IFERROR(VLOOKUP($B39,Baza_preturi!$A:$K,6,FALSE),"") -> buc | E39: 1 | F39: =IFERROR(VLOOKUP($B39,Baza_preturi!$A:$K,9,FALSE),"") -> 56250 | G39: =IF(OR($E39="", $F39=""),"", $E39*$F39) -> 56250 | H39: =IF($B39="","",IFERROR(IF(VLOOKUP($B39,Baza_preturi!$A:$A,1,FALSE)=$B39,"OK","VERIFICĂ"),"COD NU EXISTĂ")) -> OK
A40: 3. Stație de pompare | C40: =IFERROR(VLOOKUP($B40,Baza_preturi!$A:$K,3,FALSE),"") | D40: =IFERROR(VLOOKUP($B40,Baza_preturi!$A:$K,6,FALSE),"") | F40: =IFERROR(VLOOKUP($B40,Baza_preturi!$A:$K,9,FALSE),"") | G40: =IF(OR($E40="", $F40=""),"", $E40*$F40) | H40: =IF($B40="","",IFERROR(IF(VLOOKUP($B40,Baza_preturi!$A:$A,1,FALSE)=$B40,"OK","VERIFICĂ"),"COD NU EXISTĂ"))
A41: 3. Stație de pompare | C41: =IFERROR(VLOOKUP($B41,Baza_preturi!$A:$K,3,FALSE),"") | D41: =IFERROR(VLOOKUP($B41,Baza_preturi!$A:$K,6,FALSE),"") | F41: =IFERROR(VLOOKUP($B41,Baza_preturi!$A:$K,9,FALSE),"") | G41: =IF(OR($E41="", $F41=""),"", $E41*$F41) | H41: =IF($B41="","",IFERROR(IF(VLOOKUP($B41,Baza_preturi!$A:$A,1,FALSE)=$B41,"OK","VERIFICĂ"),"COD NU EXISTĂ"))
A42: 3. Stație de pompare | C42: =IFERROR(VLOOKUP($B42,Baza_preturi!$A:$K,3,FALSE),"") | D42: =IFERROR(VLOOKUP($B42,Baza_preturi!$A:$K,6,FALSE),"") | F42: =IFERROR(VLOOKUP($B42,Baza_preturi!$A:$K,9,FALSE),"") | G42: =IF(OR($E42="", $F42=""),"", $E42*$F42) | H42: =IF($B42="","",IFERROR(IF(VLOOKUP($B42,Baza_preturi!$A:$A,1,FALSE)=$B42,"OK","VERIFICĂ"),"COD NU EXISTĂ"))
A43: 3. Stație de pompare | C43: =IFERROR(VLOOKUP($B43,Baza_preturi!$A:$K,3,FALSE),"") | D43: =IFERROR(VLOOKUP($B43,Baza_preturi!$A:$K,6,FALSE),"") | F43: =IFERROR(VLOOKUP($B43,Baza_preturi!$A:$K,9,FALSE),"") | G43: =IF(OR($E43="", $F43=""),"", $E43*$F43) | H43: =IF($B43="","",IFERROR(IF(VLOOKUP($B43,Baza_preturi!$A:$A,1,FALSE)=$B43,"OK","VERIFICĂ"),"COD NU EXISTĂ"))
A44: 3. Stație de pompare | C44: =IFERROR(VLOOKUP($B44,Baza_preturi!$A:$K,3,FALSE),"") | D44: =IFERROR(VLOOKUP($B44,Baza_preturi!$A:$K,6,FALSE),"") | F44: =IFERROR(VLOOKUP($B44,Baza_preturi!$A:$K,9,FALSE),"") | G44: =IF(OR($E44="", $F44=""),"", $E44*$F44) | H44: =IF($B44="","",IFERROR(IF(VLOOKUP($B44,Baza_preturi!$A:$A,1,FALSE)=$B44,"OK","VERIFICĂ"),"COD NU EXISTĂ"))
A45: 3. Stație de pompare | C45: =IFERROR(VLOOKUP($B45,Baza_preturi!$A:$K,3,FALSE),"") | D45: =IFERROR(VLOOKUP($B45,Baza_preturi!$A:$K,6,FALSE),"") | F45: =IFERROR(VLOOKUP($B45,Baza_preturi!$A:$K,9,FALSE),"") | G45: =IF(OR($E45="", $F45=""),"", $E45*$F45) | H45: =IF($B45="","",IFERROR(IF(VLOOKUP($B45,Baza_preturi!$A:$A,1,FALSE)=$B45,"OK","VERIFICĂ"),"COD NU EXISTĂ"))
A46: 3. Stație de pompare | C46: =IFERROR(VLOOKUP($B46,Baza_preturi!$A:$K,3,FALSE),"") | D46: =IFERROR(VLOOKUP($B46,Baza_preturi!$A:$K,6,FALSE),"") | F46: =IFERROR(VLOOKUP($B46,Baza_preturi!$A:$K,9,FALSE),"") | G46: =IF(OR($E46="", $F46=""),"", $E46*$F46) | H46: =IF($B46="","",IFERROR(IF(VLOOKUP($B46,Baza_preturi!$A:$A,1,FALSE)=$B46,"OK","VERIFICĂ"),"COD NU EXISTĂ"))
...

Sheet Baza_preturi
A1: Cod | B1: Categorie | C1: Denumire standard | D1: Material | E1: DN | F1: UM | G1: Preț achiziție MDL | H1: Marjă % | I1: Preț vânzare MDL | J1: Furnizor | K1: Observații
A2: SPR-CBSO-57 | B2: Sistem sprinkler | C2: Sprinkler incendiu CBSO-PVo 0.08 R1/2 P57.B3 | D2: — | E2: — | F2: buc | G2: 124.89 | H2: =Setari!$B$3 -> 0.25 | I2: =IF(G2="","",G2*(1+H2)) -> 156.1125
A3: TEV-ZN-DN15-2.2 | B3: Țevi | C3: Țeavă zincată DN15*2.2mm | D3: zincată | E3: 15 | F3: m | H3: =Setari!$B$3 -> 0.25 | I3: =IF(G3="","",G3*(1+H3))
A4: TEV-ZN-DN15-2.8 | B4: Țevi | C4: Țeavă zincată DN15*2.8mm | D4: zincată | E4: 15 | F4: m | H4: =Setari!$B$3 -> 0.25 | I4: =IF(G4="","",G4*(1+H4))
A5: TEV-ZN-DN20-2.2 | B5: Țevi | C5: Țeavă zincată DN20*2.2mm | D5: zincată | E5: 20 | F5: m | H5: =Setari!$B$3 -> 0.25 | I5: =IF(G5="","",G5*(1+H5))
A6: TEV-ZN-DN20-2.5 | B6: Țevi | C6: Țeavă zincată DN20*2.5mm | D6: zincată | E6: 20 | F6: m | G6: 31 | H6: =Setari!$B$3 -> 0.25 | I6: =IF(G6="","",G6*(1+H6)) -> 38.75
A7: TEV-ZN-DN20-2.8 | B7: Țevi | C7: Țeavă zincată DN20*2.8mm | D7: zincată | E7: 20 | F7: m | H7: =Setari!$B$3 -> 0.25 | I7: =IF(G7="","",G7*(1+H7))
A8: TEV-ZN-DN25-2.5 | B8: Țevi | C8: Țeavă zincată DN25*2.5mm | D8: zincată | E8: 25 | F8: m | G8: 32 | H8: =Setari!$B$3 -> 0.25 | I8: =IF(G8="","",G8*(1+H8)) -> 40
A9: TEV-ZN-DN25-2.8 | B9: Țevi | C9: Țeavă zincată DN25*2.8mm | D9: zincată | E9: 25 | F9: m | H9: =Setari!$B$3 -> 0.25 | I9: =IF(G9="","",G9*(1+H9))
A10: TEV-ZN-DN25-3 | B10: Țevi | C10: Țeavă zincată DN25*3mm | D10: zincată | E10: 25 | F10: m | H10: =Setari!$B$3 -> 0.25 | I10: =IF(G10="","",G10*(1+H10))
A11: TEV-ZN-DN25-3.2 | B11: Țevi | C11: Țeavă zincată DN25*3.2mm | D11: zincată | E11: 25 | F11: m | H11: =Setari!$B$3 -> 0.25 | I11: =IF(G11="","",G11*(1+H11))
A12: TEV-ZN-DN32-2.8 | B12: Țevi | C12: Țeavă zincată DN32*2.8mm | D12: zincată | E12: 32 | F12: m | G12: 42 | H12: =Setari!$B$3 -> 0.25 | I12: =IF(G12="","",G12*(1+H12)) -> 52.5
A13: TEV-ZN-DN32-3 | B13: Țevi | C13: Țeavă zincată DN32*3mm | D13: zincată | E13: 32 | F13: m | H13: =Setari!$B$3 -> 0.25 | I13: =IF(G13="","",G13*(1+H13))
A14: TEV-ZN-DN32-3.2 | B14: Țevi | C14: Țeavă zincată DN32*3.2mm | D14: zincată | E14: 32 | F14: m | H14: =Setari!$B$3 -> 0.25 | I14: =IF(G14="","",G14*(1+H14))
A15: TEV-ZN-DN40-3 | B15: Țevi | C15: Țeavă zincată DN40*3mm | D15: zincată | E15: 40 | F15: m | H15: =Setari!$B$3 -> 0.25 | I15: =IF(G15="","",G15*(1+H15))
A16: TEV-ZN-DN40-3.2 | B16: Țevi | C16: Țeavă zincată DN40*3.2mm | D16: zincată | E16: 40 | F16: m | H16: =Setari!$B$3 -> 0.25 | I16: =IF(G16="","",G16*(1+H16))
A17: TEV-ZN-DN40-3.5 | B17: Țevi | C17: Țeavă zincată DN40*3.5mm | D17: zincată | E17: 40 | F17: m | H17: =Setari!$B$3 -> 0.25 | I17: =IF(G17="","",G17*(1+H17))
A18: TEV-ZN-DN40-4 | B18: Țevi | C18: Țeavă zincată DN40*4mm | D18: zincată | E18: 40 | F18: m | H18: =Setari!$B$3 -> 0.25 | I18: =IF(G18="","",G18*(1+H18))
A19: TEV-ZN-DN50-2.2 | B19: Țevi | C19: Țeavă zincată DN50*2.2mm | D19: zincată | E19: 50 | F19: m | H19: =Setari!$B$3 -> 0.25 | I19: =IF(G19="","",G19*(1+H19))
A20: TEV-ZN-DN50-3 | B20: Țevi | C20: Țeavă zincată DN50*3mm | D20: zincată | E20: 50 | F20: m | H20: =Setari!$B$3 -> 0.25 | I20: =IF(G20="","",G20*(1+H20))
A21: TEV-ZN-DN50-3.2 | B21: Țevi | C21: Țeavă zincată DN50*3.2mm | D21: zincată | E21: 50 | F21: m | H21: =Setari!$B$3 -> 0.25 | I21: =IF(G21="","",G21*(1+H21))
A22: TEV-ZN-DN50-3.5 | B22: Țevi | C22: Țeavă zincată DN50*3.5mm | D22: zincată | E22: 50 | F22: m | H22: =Setari!$B$3 -> 0.25 | I22: =IF(G22="","",G22*(1+H22))
A23: TEV-ZN-DN50-4 | B23: Țevi | C23: Țeavă zincată DN50*4mm | D23: zincată | E23: 50 | F23: m | H23: =Setari!$B$3 -> 0.25 | I23: =IF(G23="","",G23*(1+H23))
A24: TEV-ZN-D65-2.2 | B24: Țevi | C24: Țeavă zincată D65*2.2mm | D24: zincată | E24: 65 | F24: m | H24: =Setari!$B$3 -> 0.25 | I24: =IF(G24="","",G24*(1+H24))
... A28: TEV-ZN-D65-4 | B28: Țevi | C28: Țeavă zincată D65*4mm | D28: zincată | E28: 65 | F28: m | H28: =Setari!$B$3 -> 0.25 | I28: =IF(G28="","",G28*(1+H28))
A29: TEV-ZN-D80-3 | B29: Țevi | C29: Țeavă zincată D80*3mm | D29: zincată | E29: 80 | F29: m | G29: 96 | H29: =Setari!$B$3 -> 0.25 | I29: =IF(G29="","",G29*(1+H29)) -> 120
A30: TEV-ZN-D80-3.2 | B30: Țevi | C30: Țeavă zincată D80*3.2mm | D30: zincată | E30: 80 | F30: m | H30: =Setari!$B$3 -> 0.25 | I30: =IF(G30="","",G30*(1+H30))
A31: TEV-ZN-D80-3.5 | B31: Țevi | C31: Țeavă zincată D80*3.5mm | D31: zincată | E31: 80 | F31: m | H31: =Setari!$B$3 -> 0.25 | I31: =IF(G31="","",G31*(1+H31))
A32: TEV-ZN-D80-4 | B32: Țevi | C32: Țeavă zincată D80*4mm | D32: zincată | E32: 80 | F32: m | H32: =Setari!$B$3 -> 0.25 | I32: =IF(G32="","",G32*(1+H32))
A33: TEV-ZN-D100-3 | B33: Țevi | C33: Țeavă zincată D100*3mm | D33: zincată | E33: 100 | F33: m | G33: 133 | H33: =Setari!$B$3 -> 0.25 | I33: =IF(G33="","",G33*(1+H33)) -> 166.25
A34: TEV-ZN-D100-3.2 | B34: Țevi | C34: Țeavă zincată D100*3.2mm | D34: zincată | E34: 100 | F34: m | H34: =Setari!$B$3 -> 0.25 | I34: =IF(G34="","",G34*(1+H34))
A35: TEV-ZN-D100-3.5 | B35: Țevi | C35: Țeavă zincată D100*3.5mm | D35: zincată | E35: 100 | F35: m | H35: =Setari!$B$3 -> 0.25 | I35: =IF(G35="","",G35*(1+H35))
A36: TEV-ZN-D100-4 | B36: Țevi | C36: Țeavă zincată D100*4mm | D36: zincată | E36: 100 | F36: m | H36: =Setari!$B$3 -> 0.25 | I36: =IF(G36="","",G36*(1+H36))
A37: TEV-ZN-D100-5 | B37: Țevi | C37: Țeavă zincată D100*5mm | D37: zincată | E37: 100 | F37: m | H37: =Setari!$B$3 -> 0.25 | I37: =IF(G37="","",G37*(1+H37))
A38: TEV-ZN-D125-3.2 | B38: Țevi | C38: Țeavă zincată D125*3.2mm | D38: zincată | E38: 125 | F38: m | H38: =Setari!$B$3 -> 0.25 | I38: =IF(G38="","",G38*(1+H38))
A39: TEV-ZN-D125-4 | B39: Țevi | C39: Țeavă zincată D125*4mm | D39: zincată | E39: 125 | F39: m | H39: =Setari!$B$3 -> 0.25 | I39: =IF(G39="","",G39*(1+H39))
A40: TEV-ZN-D150-3.5 | B40: Țevi | C40: Țeavă zincată D150*3.5mm | D40: zincată | E40: 150 | F40: m | H40: =Setari!$B$3 -> 0.25 | I40: =IF(G40="","",G40*(1+H40))
A41: TEV-ZN-D150-4 | B41: Țevi | C41: Țeavă zincată D150*4mm | D41: zincată | E41: 150 | F41: m | H41: =Setari!$B$3 -> 0.25 | I41: =IF(G41="","",G41*(1+H41))
A42: TEV-ZN-D200-4 | B42: Țevi | C42: Țeavă zincată D200*4mm | D42: zincată | E42: 200 | F42: m | H42: =Setari!$B$3 -> 0.25
A43: TEV-ZN-D200-4.5 | B43: Țevi | C43: Țeavă zincată D200*4.5mm | D43: zincată | E43: 200 | F43: m | H43: =Setari!$B$3 -> 0.25
...

Sheet Sinonime
A1: Text din PDF / Specificație | B1: Cod produs | C1: Comentariu
A2: Ороситель спринклерный CBSO-ПВо 0,08-R1/2/P57.B3 | B2: SPR-CBSO-57 | C2: RU
A3: Sprinkler CBSO-ПВо 0,08-R1/2/P57.B3 | B3: SPR-CBSO-57 | C3: RO/RU mix
A4: Mufă sudată pentru pulverizatoare cu apă fină | B4: MUF-BL-DN15
A5: Mufă sudată pentru pulverizatoare | B5: MUF-BL-DN15
A6: МП G1/2 l=50 mm | B6: MUF-BL-DN15
A7: МП G1/2 | B7: MUF-BL-DN15
A8: Sprinkler cu temp. de acționare 57°C, apă | B8: SPR-CBSO-57 | C8: RO
A9: Sprinkler de incendiu CBSO | B9: SPR-CBSO-57 | C9: RO scurt
A10: Муфта приварная G 1/2 | B10: MUF-BL-DN15 | C10: RU
A11: МП G1/2, l=50 mm Mufă sudată pentru pulverizatoare cu apă fină | B11: MUF-BL-DN15
A12: 02 МП G1/2, l=50 mm Mufă sudată pentru | B12: MUF-BL-DN15 | C12: RO/PDF line
A13: Труба оцинкованная DN80 | B13: TEV-ZN-DN80 | C13: zincată
A14: Țeavă zincată DN80 | B14: TEV-ZN-DN80 | C14: zincată
A15: Teava zincata DN80 | B15: TEV-ZN-DN80 | C15: fără diacritice
A16: Труба стальная электросварная Ø89x3.5 | B16: TEV-BL-DN80 | C16: negru
A17: Teava DU80 | B17: TEV-BL-DN80 | C17: negru
A18: Țeavă oțel negru DN80 | B18: TEV-BL-DN80 | C18: negru
A19: Отвод DN50 | B19: COT-ZN-DN50 | C19: verifică materialul dacă nu este clar
A20: Cot zincat DN50 | B20: COT-ZN-DN50 | C20: zincată
A21: Cot negru DN50 | B21: COT-BL-DN50 | C21: negru
A22: Тройник DN80 | B22: TEU-ZN-DN80 | C22: verifică materialul dacă nu este clar
A23: Teu zincat DN80 | B23: TEU-ZN-DN80 | C23: zincată
... A69: Tijă filetată M8 | B69: TIJA-M8 | C69: RO
A70: Rețeaua de sprinklere | C70: titlu / ignoră

Sheet Setari
A1: Parametru | B1: Valoare
A2: TVA | B2: 0.2
A3: Marjă implicită | B3: 0.25
A4: Valută | B4: MDL
A5: Regulă principală | B5: 1 produs unic = 1 cod intern; toate denumirile alternative merg în Sinonime
